<?xml version="1.0"?>

<!-- DESCRIPTION: Bicycle Model that follows parameterization in Meijaard (2007) and uses 
geometric and inertial values from Astrom (2005)
UNITS: All distances in meters, all angles in radians, all masses in kg-->

<robot name="bicycle" xmlns:xacro="http://www.ros.org/wiki/xacro">
<!-- CAD URL: https://cad.onshape.com/documents/e5ef9716c5b71004058bf9ce/w/ae8819e9743ff8e3d490a09a/e/5a0b072f3be44112fc069069 -->

  <!-- Import baseline model -->
  <xacro:include filename="$(find bicycle_description)/urdf/baseline_model.urdf.xacro" />

  <!-- Import gazebo specific tags for this model -->
  <xacro:include filename="$(find bicycle_description)/urdf/flywheel.gazebo" />

  <!-- ______Inertia Parameters______ -->
  <xacro:property name="m_f" value="${1.3}"/>

  <xacro:property name="I_fxx" value="${0.005}"/>
  <xacro:property name="I_fyy" value="${0.002}"/>
  <xacro:property name="I_fzz" value="${0.002}"/>
  <xacro:property name="I_fxy" value="${0}"/>
  <xacro:property name="I_fxz" value="${0}"/>
  <xacro:property name="I_fyz" value="${0}"/>

  <xacro:property name="x_f" value="${0}"/>
  <xacro:property name="y_f" value="${0}"/>
  <xacro:property name="z_f" value="${0}"/>


  <!--***********************************-->
  <!--_______FLYWHEEL LINK AND JOINT_____-->
  <!--***********************************-->

  <!-- Flywheel mesh has origin at center, and is oriented with x-axis along flywheel
  spin axis. -->
  
   <link name="flywheel">
    <visual>
      <origin rpy="0 0 0" xyz="0 0 0"/>
      <geometry>
          <mesh filename="package://bicycle_description/meshes/gyro_model/flywheel.stl" />
      </geometry>
      <material name="green"/>
    </visual>

    <collision>
      <origin rpy="0 0 0" xyz="0 0 0"/>
      <geometry>
          <mesh filename="package://bicycle_description/meshes/gyro_model/flywheel.stl" />
      </geometry>
    </collision>

    <inertial>
      <origin rpy="0 0 0" xyz="${x_f} ${y_f} ${z_f}"/>
      <mass value="${m_f}"/>
      <inertia ixx="${I_fxx}" ixy="${I_fxy}" ixz="${I_fxy}"
               iyy="${I_fyy}" iyz="${I_fyz}"
               izz="${I_fzz}" />
    </inertial>
  </link>

  <!-- Connects the flywheel to the back_frame. The xyz offset is relative to center 
  of back_wheel axle (where back_frame's joint frame is at).  -->
  <joint name="flywheel_joint" type="continuous">
    <parent link="back_frame"/>
    <child link="flywheel"/>
    <origin xyz="0.4 0 0.7" rpy="0 0 ${PI/2}"/>
    <axis xyz="0 1 0"/>
    <dynamic damping="0" friction="0.002" />
  </joint>

</robot>
